package lab9.task1;

public class Example1 {
    public static void main(String[] args) {
        try {
            System.out.println("0");
            throw  new RuntimeException("Непроверяемая ошибка");
        } catch (RuntimeException e) { // исключение перехвачено
            System.out.println("1  "+ e);  // исключение обработано
        }
        System.out.println("2");
    }
}
/*
Пример 1 демонстрирует сгенерирование и перехват исключения типа RuntimeException в методе main().
В данном примере, после вывода на консоль строки "0", генерируется новый объект исключения RuntimeException с сообщением "Непроверяемая ошибка" при помощи оператора throw.
Затем исключение перехватывается блоком try-catch. Исключение типа RuntimeException является непроверяемым исключением, поэтому оно не требует объявления или обработки в сигнатуре метода.
В блоке catch мы получаем доступ к объекту исключения при помощи переменной e и выводим на консоль строку "1" и информацию об исключении.
Далее, программа продолжает своё выполнение и выводит строку "2".
 */
